SearchBayesianSkoptObject: Config 0 Exception. Config: {'strategy': 'weighted_count', 'multiplier_cutoff': 2, 'MIXED': 0.8853031372180766, 'SLIM_BPR': 0.724700463605893, 'P3ALPHA': 0.0796422701120545, 'RP3BETA': 0.04344503224886998, 'IALS': 0.5398577116728893, 'USER_ITEM_ALL': 0.140655147062314} - Exception: Traceback (most recent call last):
  File "C:\Users\User.LAPTOP-FG37H74P\Documents\GitHub\recsys_2019\src\tuning\SearchFixedObject.py", line 285, in _objective_function
    result_dict, result_string, recommender_instance, train_time, evaluation_time = self._evaluate_on_validation(current_fit_parameters_dict)
  File "C:\Users\User.LAPTOP-FG37H74P\Documents\GitHub\recsys_2019\src\tuning\SearchFixedObject.py", line 196, in _evaluate_on_validation
    result_dict, _ = self.evaluator_validation.evaluateRecommender(recommender_instance)
  File "C:\Users\User.LAPTOP-FG37H74P\Documents\GitHub\recsys_2019\course_lib\Base\Evaluation\Evaluator.py", line 384, in evaluateRecommender
    self.usersToEvaluate)
  File "C:\Users\User.LAPTOP-FG37H74P\Documents\GitHub\recsys_2019\course_lib\Base\Evaluation\Evaluator.py", line 278, in _run_evaluation_on_selected_users
    return_scores=True
  File "C:\Users\User.LAPTOP-FG37H74P\Documents\GitHub\recsys_2019\src\model\HybridRecommender\HybridRankBasedRecommender.py", line 164, in recommend
    rankings, scores = recommender_model.recommend(user_id_array, cutoff=cutoff_model,
AttributeError: 'dict' object has no attribute 'recommend'

SearchBayesianSkoptObject: Config 1 Exception. Config: {'strategy': 'weighted_count', 'multiplier_cutoff': 8, 'MIXED': 0.46789665161612726, 'SLIM_BPR': 0.7608712219382735, 'P3ALPHA': 0.6020193251734823, 'RP3BETA': 0.7380854505292647, 'IALS': 0.15868847601762529, 'USER_ITEM_ALL': 0.19084172207746414} - Exception: Traceback (most recent call last):
  File "C:\Users\User.LAPTOP-FG37H74P\Documents\GitHub\recsys_2019\src\tuning\SearchFixedObject.py", line 285, in _objective_function
    result_dict, result_string, recommender_instance, train_time, evaluation_time = self._evaluate_on_validation(current_fit_parameters_dict)
  File "C:\Users\User.LAPTOP-FG37H74P\Documents\GitHub\recsys_2019\src\tuning\SearchFixedObject.py", line 196, in _evaluate_on_validation
    result_dict, _ = self.evaluator_validation.evaluateRecommender(recommender_instance)
  File "C:\Users\User.LAPTOP-FG37H74P\Documents\GitHub\recsys_2019\course_lib\Base\Evaluation\Evaluator.py", line 384, in evaluateRecommender
    self.usersToEvaluate)
  File "C:\Users\User.LAPTOP-FG37H74P\Documents\GitHub\recsys_2019\course_lib\Base\Evaluation\Evaluator.py", line 278, in _run_evaluation_on_selected_users
    return_scores=True
  File "C:\Users\User.LAPTOP-FG37H74P\Documents\GitHub\recsys_2019\src\model\HybridRecommender\HybridRankBasedRecommender.py", line 164, in recommend
    rankings, scores = recommender_model.recommend(user_id_array, cutoff=cutoff_model,
AttributeError: 'dict' object has no attribute 'recommend'

SearchBayesianSkoptObject: Config 2 Exception. Config: {'strategy': 'weighted_count', 'multiplier_cutoff': 7, 'MIXED': 0.35624200124757727, 'SLIM_BPR': 0.36830503662683794, 'P3ALPHA': 0.04925828079790996, 'RP3BETA': 0.8528904286889414, 'IALS': 0.11562204485201114, 'USER_ITEM_ALL': 0.8665402435995131} - Exception: Traceback (most recent call last):
  File "C:\Users\User.LAPTOP-FG37H74P\Documents\GitHub\recsys_2019\src\tuning\SearchFixedObject.py", line 285, in _objective_function
    result_dict, result_string, recommender_instance, train_time, evaluation_time = self._evaluate_on_validation(current_fit_parameters_dict)
  File "C:\Users\User.LAPTOP-FG37H74P\Documents\GitHub\recsys_2019\src\tuning\SearchFixedObject.py", line 196, in _evaluate_on_validation
    result_dict, _ = self.evaluator_validation.evaluateRecommender(recommender_instance)
  File "C:\Users\User.LAPTOP-FG37H74P\Documents\GitHub\recsys_2019\course_lib\Base\Evaluation\Evaluator.py", line 384, in evaluateRecommender
    self.usersToEvaluate)
  File "C:\Users\User.LAPTOP-FG37H74P\Documents\GitHub\recsys_2019\course_lib\Base\Evaluation\Evaluator.py", line 278, in _run_evaluation_on_selected_users
    return_scores=True
  File "C:\Users\User.LAPTOP-FG37H74P\Documents\GitHub\recsys_2019\src\model\HybridRecommender\HybridRankBasedRecommender.py", line 164, in recommend
    rankings, scores = recommender_model.recommend(user_id_array, cutoff=cutoff_model,
AttributeError: 'dict' object has no attribute 'recommend'

SearchBayesianSkoptObject: Config 3 Exception. Config: {'strategy': 'weighted_count', 'multiplier_cutoff': 9, 'MIXED': 0.2574216866247189, 'SLIM_BPR': 0.4516481074323604, 'P3ALPHA': 0.5840546633939983, 'RP3BETA': 0.7713881638964113, 'IALS': 0.07614028070997726, 'USER_ITEM_ALL': 0.3638769093157173} - Exception: Traceback (most recent call last):
  File "C:\Users\User.LAPTOP-FG37H74P\Documents\GitHub\recsys_2019\src\tuning\SearchFixedObject.py", line 285, in _objective_function
    result_dict, result_string, recommender_instance, train_time, evaluation_time = self._evaluate_on_validation(current_fit_parameters_dict)
  File "C:\Users\User.LAPTOP-FG37H74P\Documents\GitHub\recsys_2019\src\tuning\SearchFixedObject.py", line 196, in _evaluate_on_validation
    result_dict, _ = self.evaluator_validation.evaluateRecommender(recommender_instance)
  File "C:\Users\User.LAPTOP-FG37H74P\Documents\GitHub\recsys_2019\course_lib\Base\Evaluation\Evaluator.py", line 384, in evaluateRecommender
    self.usersToEvaluate)
  File "C:\Users\User.LAPTOP-FG37H74P\Documents\GitHub\recsys_2019\course_lib\Base\Evaluation\Evaluator.py", line 278, in _run_evaluation_on_selected_users
    return_scores=True
  File "C:\Users\User.LAPTOP-FG37H74P\Documents\GitHub\recsys_2019\src\model\HybridRecommender\HybridRankBasedRecommender.py", line 164, in recommend
    rankings, scores = recommender_model.recommend(user_id_array, cutoff=cutoff_model,
AttributeError: 'dict' object has no attribute 'recommend'

SearchBayesianSkoptObject: Config 4 Exception. Config: {'strategy': 'weighted_count', 'multiplier_cutoff': 6, 'MIXED': 0.6385077617175373, 'SLIM_BPR': 0.29428306425336076, 'P3ALPHA': 0.9768987738550585, 'RP3BETA': 0.7347196545897094, 'IALS': 0.941806090286749, 'USER_ITEM_ALL': 0.9637302803448744} - Exception: Traceback (most recent call last):
  File "C:\Users\User.LAPTOP-FG37H74P\Documents\GitHub\recsys_2019\src\tuning\SearchFixedObject.py", line 285, in _objective_function
    result_dict, result_string, recommender_instance, train_time, evaluation_time = self._evaluate_on_validation(current_fit_parameters_dict)
  File "C:\Users\User.LAPTOP-FG37H74P\Documents\GitHub\recsys_2019\src\tuning\SearchFixedObject.py", line 196, in _evaluate_on_validation
    result_dict, _ = self.evaluator_validation.evaluateRecommender(recommender_instance)
  File "C:\Users\User.LAPTOP-FG37H74P\Documents\GitHub\recsys_2019\course_lib\Base\Evaluation\Evaluator.py", line 384, in evaluateRecommender
    self.usersToEvaluate)
  File "C:\Users\User.LAPTOP-FG37H74P\Documents\GitHub\recsys_2019\course_lib\Base\Evaluation\Evaluator.py", line 278, in _run_evaluation_on_selected_users
    return_scores=True
  File "C:\Users\User.LAPTOP-FG37H74P\Documents\GitHub\recsys_2019\src\model\HybridRecommender\HybridRankBasedRecommender.py", line 164, in recommend
    rankings, scores = recommender_model.recommend(user_id_array, cutoff=cutoff_model,
AttributeError: 'dict' object has no attribute 'recommend'

SearchBayesianSkoptObject: Config 5 Exception. Config: {'strategy': 'weighted_count', 'multiplier_cutoff': 1, 'MIXED': 0.06297855512827456, 'SLIM_BPR': 0.14600317345540995, 'P3ALPHA': 0.7808343224930064, 'RP3BETA': 0.14756395277060189, 'IALS': 0.8534229597009503, 'USER_ITEM_ALL': 0.9810770472424665} - Exception: Traceback (most recent call last):
  File "C:\Users\User.LAPTOP-FG37H74P\Documents\GitHub\recsys_2019\src\tuning\SearchFixedObject.py", line 285, in _objective_function
    result_dict, result_string, recommender_instance, train_time, evaluation_time = self._evaluate_on_validation(current_fit_parameters_dict)
  File "C:\Users\User.LAPTOP-FG37H74P\Documents\GitHub\recsys_2019\src\tuning\SearchFixedObject.py", line 196, in _evaluate_on_validation
    result_dict, _ = self.evaluator_validation.evaluateRecommender(recommender_instance)
  File "C:\Users\User.LAPTOP-FG37H74P\Documents\GitHub\recsys_2019\course_lib\Base\Evaluation\Evaluator.py", line 384, in evaluateRecommender
    self.usersToEvaluate)
  File "C:\Users\User.LAPTOP-FG37H74P\Documents\GitHub\recsys_2019\course_lib\Base\Evaluation\Evaluator.py", line 278, in _run_evaluation_on_selected_users
    return_scores=True
  File "C:\Users\User.LAPTOP-FG37H74P\Documents\GitHub\recsys_2019\src\model\HybridRecommender\HybridRankBasedRecommender.py", line 164, in recommend
    rankings, scores = recommender_model.recommend(user_id_array, cutoff=cutoff_model,
AttributeError: 'dict' object has no attribute 'recommend'

SearchBayesianSkoptObject: Config 6 Exception. Config: {'strategy': 'weighted_count', 'multiplier_cutoff': 9, 'MIXED': 0.11783100909211777, 'SLIM_BPR': 0.9343881396045539, 'P3ALPHA': 0.9924968575433439, 'RP3BETA': 0.07764869923506569, 'IALS': 0.8250140644337614, 'USER_ITEM_ALL': 0.02026915564136556} - Exception: Traceback (most recent call last):
  File "C:\Users\User.LAPTOP-FG37H74P\Documents\GitHub\recsys_2019\src\tuning\SearchFixedObject.py", line 285, in _objective_function
    result_dict, result_string, recommender_instance, train_time, evaluation_time = self._evaluate_on_validation(current_fit_parameters_dict)
  File "C:\Users\User.LAPTOP-FG37H74P\Documents\GitHub\recsys_2019\src\tuning\SearchFixedObject.py", line 196, in _evaluate_on_validation
    result_dict, _ = self.evaluator_validation.evaluateRecommender(recommender_instance)
  File "C:\Users\User.LAPTOP-FG37H74P\Documents\GitHub\recsys_2019\course_lib\Base\Evaluation\Evaluator.py", line 384, in evaluateRecommender
    self.usersToEvaluate)
  File "C:\Users\User.LAPTOP-FG37H74P\Documents\GitHub\recsys_2019\course_lib\Base\Evaluation\Evaluator.py", line 278, in _run_evaluation_on_selected_users
    return_scores=True
  File "C:\Users\User.LAPTOP-FG37H74P\Documents\GitHub\recsys_2019\src\model\HybridRecommender\HybridRankBasedRecommender.py", line 164, in recommend
    rankings, scores = recommender_model.recommend(user_id_array, cutoff=cutoff_model,
AttributeError: 'dict' object has no attribute 'recommend'

SearchBayesianSkoptObject: Config 7 Exception. Config: {'strategy': 'weighted_count', 'multiplier_cutoff': 1, 'MIXED': 0.9597285287314866, 'SLIM_BPR': 0.09756500266479032, 'P3ALPHA': 0.9807103242833527, 'RP3BETA': 0.04082140229747134, 'IALS': 0.9308397598607744, 'USER_ITEM_ALL': 0.01005258996294345} - Exception: Traceback (most recent call last):
  File "C:\Users\User.LAPTOP-FG37H74P\Documents\GitHub\recsys_2019\src\tuning\SearchFixedObject.py", line 285, in _objective_function
    result_dict, result_string, recommender_instance, train_time, evaluation_time = self._evaluate_on_validation(current_fit_parameters_dict)
  File "C:\Users\User.LAPTOP-FG37H74P\Documents\GitHub\recsys_2019\src\tuning\SearchFixedObject.py", line 196, in _evaluate_on_validation
    result_dict, _ = self.evaluator_validation.evaluateRecommender(recommender_instance)
  File "C:\Users\User.LAPTOP-FG37H74P\Documents\GitHub\recsys_2019\course_lib\Base\Evaluation\Evaluator.py", line 384, in evaluateRecommender
    self.usersToEvaluate)
  File "C:\Users\User.LAPTOP-FG37H74P\Documents\GitHub\recsys_2019\course_lib\Base\Evaluation\Evaluator.py", line 278, in _run_evaluation_on_selected_users
    return_scores=True
  File "C:\Users\User.LAPTOP-FG37H74P\Documents\GitHub\recsys_2019\src\model\HybridRecommender\HybridRankBasedRecommender.py", line 164, in recommend
    rankings, scores = recommender_model.recommend(user_id_array, cutoff=cutoff_model,
AttributeError: 'dict' object has no attribute 'recommend'

SearchBayesianSkoptObject: Config 8 Exception. Config: {'strategy': 'weighted_count', 'multiplier_cutoff': 1, 'MIXED': 0.9643872881223322, 'SLIM_BPR': 0.9195504230304753, 'P3ALPHA': 0.08026818470571818, 'RP3BETA': 0.9313300634872573, 'IALS': 0.026865087725191368, 'USER_ITEM_ALL': 0.9444803116865881} - Exception: Traceback (most recent call last):
  File "C:\Users\User.LAPTOP-FG37H74P\Documents\GitHub\recsys_2019\src\tuning\SearchFixedObject.py", line 285, in _objective_function
    result_dict, result_string, recommender_instance, train_time, evaluation_time = self._evaluate_on_validation(current_fit_parameters_dict)
  File "C:\Users\User.LAPTOP-FG37H74P\Documents\GitHub\recsys_2019\src\tuning\SearchFixedObject.py", line 196, in _evaluate_on_validation
    result_dict, _ = self.evaluator_validation.evaluateRecommender(recommender_instance)
  File "C:\Users\User.LAPTOP-FG37H74P\Documents\GitHub\recsys_2019\course_lib\Base\Evaluation\Evaluator.py", line 384, in evaluateRecommender
    self.usersToEvaluate)
  File "C:\Users\User.LAPTOP-FG37H74P\Documents\GitHub\recsys_2019\course_lib\Base\Evaluation\Evaluator.py", line 278, in _run_evaluation_on_selected_users
    return_scores=True
  File "C:\Users\User.LAPTOP-FG37H74P\Documents\GitHub\recsys_2019\src\model\HybridRecommender\HybridRankBasedRecommender.py", line 164, in recommend
    rankings, scores = recommender_model.recommend(user_id_array, cutoff=cutoff_model,
AttributeError: 'dict' object has no attribute 'recommend'

SearchBayesianSkoptObject: Config 9 Exception. Config: {'strategy': 'weighted_count', 'multiplier_cutoff': 9, 'MIXED': 0.964099382471958, 'SLIM_BPR': 0.11588948284056069, 'P3ALPHA': 0.02258916749672735, 'RP3BETA': 0.034156762114934465, 'IALS': 0.035750996306562983, 'USER_ITEM_ALL': 0.0055771897164416115} - Exception: Traceback (most recent call last):
  File "C:\Users\User.LAPTOP-FG37H74P\Documents\GitHub\recsys_2019\src\tuning\SearchFixedObject.py", line 285, in _objective_function
    result_dict, result_string, recommender_instance, train_time, evaluation_time = self._evaluate_on_validation(current_fit_parameters_dict)
  File "C:\Users\User.LAPTOP-FG37H74P\Documents\GitHub\recsys_2019\src\tuning\SearchFixedObject.py", line 196, in _evaluate_on_validation
    result_dict, _ = self.evaluator_validation.evaluateRecommender(recommender_instance)
  File "C:\Users\User.LAPTOP-FG37H74P\Documents\GitHub\recsys_2019\course_lib\Base\Evaluation\Evaluator.py", line 384, in evaluateRecommender
    self.usersToEvaluate)
  File "C:\Users\User.LAPTOP-FG37H74P\Documents\GitHub\recsys_2019\course_lib\Base\Evaluation\Evaluator.py", line 278, in _run_evaluation_on_selected_users
    return_scores=True
  File "C:\Users\User.LAPTOP-FG37H74P\Documents\GitHub\recsys_2019\src\model\HybridRecommender\HybridRankBasedRecommender.py", line 164, in recommend
    rankings, scores = recommender_model.recommend(user_id_array, cutoff=cutoff_model,
AttributeError: 'dict' object has no attribute 'recommend'

SearchBayesianSkoptObject: Config 10 Exception. Config: {'strategy': 'weighted_count', 'multiplier_cutoff': 1, 'MIXED': 0.04738311137545416, 'SLIM_BPR': 0.09152691210379772, 'P3ALPHA': 0.07704501480310978, 'RP3BETA': 0.8438505330246552, 'IALS': 0.1027670386693337, 'USER_ITEM_ALL': 0.021570413888784893} - Exception: Traceback (most recent call last):
  File "C:\Users\User.LAPTOP-FG37H74P\Documents\GitHub\recsys_2019\src\tuning\SearchFixedObject.py", line 285, in _objective_function
    result_dict, result_string, recommender_instance, train_time, evaluation_time = self._evaluate_on_validation(current_fit_parameters_dict)
  File "C:\Users\User.LAPTOP-FG37H74P\Documents\GitHub\recsys_2019\src\tuning\SearchFixedObject.py", line 196, in _evaluate_on_validation
    result_dict, _ = self.evaluator_validation.evaluateRecommender(recommender_instance)
  File "C:\Users\User.LAPTOP-FG37H74P\Documents\GitHub\recsys_2019\course_lib\Base\Evaluation\Evaluator.py", line 384, in evaluateRecommender
    self.usersToEvaluate)
  File "C:\Users\User.LAPTOP-FG37H74P\Documents\GitHub\recsys_2019\course_lib\Base\Evaluation\Evaluator.py", line 278, in _run_evaluation_on_selected_users
    return_scores=True
  File "C:\Users\User.LAPTOP-FG37H74P\Documents\GitHub\recsys_2019\src\model\HybridRecommender\HybridRankBasedRecommender.py", line 164, in recommend
    rankings, scores = recommender_model.recommend(user_id_array, cutoff=cutoff_model,
AttributeError: 'dict' object has no attribute 'recommend'

SearchBayesianSkoptObject: Config 11 Exception. Config: {'strategy': 'weighted_count', 'multiplier_cutoff': 9, 'MIXED': 0.939546214575479, 'SLIM_BPR': 0.022632472875648627, 'P3ALPHA': 0.979875906212384, 'RP3BETA': 0.2082589031193413, 'IALS': 0.9636734160137759, 'USER_ITEM_ALL': 0.9788789697291145} - Exception: Traceback (most recent call last):
  File "C:\Users\User.LAPTOP-FG37H74P\Documents\GitHub\recsys_2019\src\tuning\SearchFixedObject.py", line 285, in _objective_function
    result_dict, result_string, recommender_instance, train_time, evaluation_time = self._evaluate_on_validation(current_fit_parameters_dict)
  File "C:\Users\User.LAPTOP-FG37H74P\Documents\GitHub\recsys_2019\src\tuning\SearchFixedObject.py", line 196, in _evaluate_on_validation
    result_dict, _ = self.evaluator_validation.evaluateRecommender(recommender_instance)
  File "C:\Users\User.LAPTOP-FG37H74P\Documents\GitHub\recsys_2019\course_lib\Base\Evaluation\Evaluator.py", line 384, in evaluateRecommender
    self.usersToEvaluate)
  File "C:\Users\User.LAPTOP-FG37H74P\Documents\GitHub\recsys_2019\course_lib\Base\Evaluation\Evaluator.py", line 278, in _run_evaluation_on_selected_users
    return_scores=True
  File "C:\Users\User.LAPTOP-FG37H74P\Documents\GitHub\recsys_2019\src\model\HybridRecommender\HybridRankBasedRecommender.py", line 164, in recommend
    rankings, scores = recommender_model.recommend(user_id_array, cutoff=cutoff_model,
AttributeError: 'dict' object has no attribute 'recommend'

SearchBayesianSkoptObject: Config 12 Exception. Config: {'strategy': 'weighted_count', 'multiplier_cutoff': 9, 'MIXED': 0.012398890261121372, 'SLIM_BPR': 0.5991868412727723, 'P3ALPHA': 0.0629319342366064, 'RP3BETA': 0.9472803163987874, 'IALS': 1.0, 'USER_ITEM_ALL': 0.10802002042803775} - Exception: Traceback (most recent call last):
  File "C:\Users\User.LAPTOP-FG37H74P\Documents\GitHub\recsys_2019\src\tuning\SearchFixedObject.py", line 285, in _objective_function
    result_dict, result_string, recommender_instance, train_time, evaluation_time = self._evaluate_on_validation(current_fit_parameters_dict)
  File "C:\Users\User.LAPTOP-FG37H74P\Documents\GitHub\recsys_2019\src\tuning\SearchFixedObject.py", line 196, in _evaluate_on_validation
    result_dict, _ = self.evaluator_validation.evaluateRecommender(recommender_instance)
  File "C:\Users\User.LAPTOP-FG37H74P\Documents\GitHub\recsys_2019\course_lib\Base\Evaluation\Evaluator.py", line 384, in evaluateRecommender
    self.usersToEvaluate)
  File "C:\Users\User.LAPTOP-FG37H74P\Documents\GitHub\recsys_2019\course_lib\Base\Evaluation\Evaluator.py", line 278, in _run_evaluation_on_selected_users
    return_scores=True
  File "C:\Users\User.LAPTOP-FG37H74P\Documents\GitHub\recsys_2019\src\model\HybridRecommender\HybridRankBasedRecommender.py", line 164, in recommend
    rankings, scores = recommender_model.recommend(user_id_array, cutoff=cutoff_model,
AttributeError: 'dict' object has no attribute 'recommend'

SearchBayesianSkoptObject: Config 13 Exception. Config: {'strategy': 'weighted_count', 'multiplier_cutoff': 3, 'MIXED': 0.01046714725746878, 'SLIM_BPR': 0.8671432550514839, 'P3ALPHA': 0.9688908764984255, 'RP3BETA': 0.06486092736771755, 'IALS': 0.21712088524543666, 'USER_ITEM_ALL': 0.9648840816358661} - Exception: Traceback (most recent call last):
  File "C:\Users\User.LAPTOP-FG37H74P\Documents\GitHub\recsys_2019\src\tuning\SearchFixedObject.py", line 285, in _objective_function
    result_dict, result_string, recommender_instance, train_time, evaluation_time = self._evaluate_on_validation(current_fit_parameters_dict)
  File "C:\Users\User.LAPTOP-FG37H74P\Documents\GitHub\recsys_2019\src\tuning\SearchFixedObject.py", line 196, in _evaluate_on_validation
    result_dict, _ = self.evaluator_validation.evaluateRecommender(recommender_instance)
  File "C:\Users\User.LAPTOP-FG37H74P\Documents\GitHub\recsys_2019\course_lib\Base\Evaluation\Evaluator.py", line 384, in evaluateRecommender
    self.usersToEvaluate)
  File "C:\Users\User.LAPTOP-FG37H74P\Documents\GitHub\recsys_2019\course_lib\Base\Evaluation\Evaluator.py", line 278, in _run_evaluation_on_selected_users
    return_scores=True
  File "C:\Users\User.LAPTOP-FG37H74P\Documents\GitHub\recsys_2019\src\model\HybridRecommender\HybridRankBasedRecommender.py", line 164, in recommend
    rankings, scores = recommender_model.recommend(user_id_array, cutoff=cutoff_model,
AttributeError: 'dict' object has no attribute 'recommend'

SearchBayesianSkoptObject: Config 14 Exception. Config: {'strategy': 'weighted_count', 'multiplier_cutoff': 1, 'MIXED': 0.979791577722242, 'SLIM_BPR': 0.9716862783128751, 'P3ALPHA': 0.002456773158825421, 'RP3BETA': 0.9233702328980778, 'IALS': 0.6817815882445382, 'USER_ITEM_ALL': 0.008445570485065114} - Exception: Traceback (most recent call last):
  File "C:\Users\User.LAPTOP-FG37H74P\Documents\GitHub\recsys_2019\src\tuning\SearchFixedObject.py", line 285, in _objective_function
    result_dict, result_string, recommender_instance, train_time, evaluation_time = self._evaluate_on_validation(current_fit_parameters_dict)
  File "C:\Users\User.LAPTOP-FG37H74P\Documents\GitHub\recsys_2019\src\tuning\SearchFixedObject.py", line 196, in _evaluate_on_validation
    result_dict, _ = self.evaluator_validation.evaluateRecommender(recommender_instance)
  File "C:\Users\User.LAPTOP-FG37H74P\Documents\GitHub\recsys_2019\course_lib\Base\Evaluation\Evaluator.py", line 384, in evaluateRecommender
    self.usersToEvaluate)
  File "C:\Users\User.LAPTOP-FG37H74P\Documents\GitHub\recsys_2019\course_lib\Base\Evaluation\Evaluator.py", line 278, in _run_evaluation_on_selected_users
    return_scores=True
  File "C:\Users\User.LAPTOP-FG37H74P\Documents\GitHub\recsys_2019\src\model\HybridRecommender\HybridRankBasedRecommender.py", line 164, in recommend
    rankings, scores = recommender_model.recommend(user_id_array, cutoff=cutoff_model,
AttributeError: 'dict' object has no attribute 'recommend'

SearchBayesianSkoptObject: Config 15 Exception. Config: {'strategy': 'weighted_count', 'multiplier_cutoff': 7, 'MIXED': 0.9652197672819026, 'SLIM_BPR': 0.0035997240574898734, 'P3ALPHA': 0.9854225367182241, 'RP3BETA': 0.8946005514879677, 'IALS': 0.013485369411977758, 'USER_ITEM_ALL': 0.046757009265417045} - Exception: Traceback (most recent call last):
  File "C:\Users\User.LAPTOP-FG37H74P\Documents\GitHub\recsys_2019\src\tuning\SearchFixedObject.py", line 285, in _objective_function
    result_dict, result_string, recommender_instance, train_time, evaluation_time = self._evaluate_on_validation(current_fit_parameters_dict)
  File "C:\Users\User.LAPTOP-FG37H74P\Documents\GitHub\recsys_2019\src\tuning\SearchFixedObject.py", line 196, in _evaluate_on_validation
    result_dict, _ = self.evaluator_validation.evaluateRecommender(recommender_instance)
  File "C:\Users\User.LAPTOP-FG37H74P\Documents\GitHub\recsys_2019\course_lib\Base\Evaluation\Evaluator.py", line 384, in evaluateRecommender
    self.usersToEvaluate)
  File "C:\Users\User.LAPTOP-FG37H74P\Documents\GitHub\recsys_2019\course_lib\Base\Evaluation\Evaluator.py", line 278, in _run_evaluation_on_selected_users
    return_scores=True
  File "C:\Users\User.LAPTOP-FG37H74P\Documents\GitHub\recsys_2019\src\model\HybridRecommender\HybridRankBasedRecommender.py", line 164, in recommend
    rankings, scores = recommender_model.recommend(user_id_array, cutoff=cutoff_model,
AttributeError: 'dict' object has no attribute 'recommend'

SearchBayesianSkoptObject: Config 16 Exception. Config: {'strategy': 'weighted_count', 'multiplier_cutoff': 10, 'MIXED': 0.001696569788862679, 'SLIM_BPR': 0.034829238608199205, 'P3ALPHA': 0.02527739847618505, 'RP3BETA': 0.7583520484470149, 'IALS': 0.8664980460465841, 'USER_ITEM_ALL': 0.9409656764225774} - Exception: Traceback (most recent call last):
  File "C:\Users\User.LAPTOP-FG37H74P\Documents\GitHub\recsys_2019\src\tuning\SearchFixedObject.py", line 285, in _objective_function
    result_dict, result_string, recommender_instance, train_time, evaluation_time = self._evaluate_on_validation(current_fit_parameters_dict)
  File "C:\Users\User.LAPTOP-FG37H74P\Documents\GitHub\recsys_2019\src\tuning\SearchFixedObject.py", line 196, in _evaluate_on_validation
    result_dict, _ = self.evaluator_validation.evaluateRecommender(recommender_instance)
  File "C:\Users\User.LAPTOP-FG37H74P\Documents\GitHub\recsys_2019\course_lib\Base\Evaluation\Evaluator.py", line 384, in evaluateRecommender
    self.usersToEvaluate)
  File "C:\Users\User.LAPTOP-FG37H74P\Documents\GitHub\recsys_2019\course_lib\Base\Evaluation\Evaluator.py", line 278, in _run_evaluation_on_selected_users
    return_scores=True
  File "C:\Users\User.LAPTOP-FG37H74P\Documents\GitHub\recsys_2019\src\model\HybridRecommender\HybridRankBasedRecommender.py", line 164, in recommend
    rankings, scores = recommender_model.recommend(user_id_array, cutoff=cutoff_model,
AttributeError: 'dict' object has no attribute 'recommend'

SearchBayesianSkoptObject: Config 17 Exception. Config: {'strategy': 'weighted_count', 'multiplier_cutoff': 10, 'MIXED': 0.6264859284457382, 'SLIM_BPR': 0.8452884502105118, 'P3ALPHA': 0.008035035582862006, 'RP3BETA': 0.028651303033638505, 'IALS': 0.955716173859647, 'USER_ITEM_ALL': 0.8766945170884358} - Exception: Traceback (most recent call last):
  File "C:\Users\User.LAPTOP-FG37H74P\Documents\GitHub\recsys_2019\src\tuning\SearchFixedObject.py", line 285, in _objective_function
    result_dict, result_string, recommender_instance, train_time, evaluation_time = self._evaluate_on_validation(current_fit_parameters_dict)
  File "C:\Users\User.LAPTOP-FG37H74P\Documents\GitHub\recsys_2019\src\tuning\SearchFixedObject.py", line 196, in _evaluate_on_validation
    result_dict, _ = self.evaluator_validation.evaluateRecommender(recommender_instance)
  File "C:\Users\User.LAPTOP-FG37H74P\Documents\GitHub\recsys_2019\course_lib\Base\Evaluation\Evaluator.py", line 384, in evaluateRecommender
    self.usersToEvaluate)
  File "C:\Users\User.LAPTOP-FG37H74P\Documents\GitHub\recsys_2019\course_lib\Base\Evaluation\Evaluator.py", line 278, in _run_evaluation_on_selected_users
    return_scores=True
  File "C:\Users\User.LAPTOP-FG37H74P\Documents\GitHub\recsys_2019\src\model\HybridRecommender\HybridRankBasedRecommender.py", line 164, in recommend
    rankings, scores = recommender_model.recommend(user_id_array, cutoff=cutoff_model,
AttributeError: 'dict' object has no attribute 'recommend'

SearchBayesianSkoptObject: Config 18 Exception. Config: {'strategy': 'weighted_count', 'multiplier_cutoff': 1, 'MIXED': 0.008117478442264183, 'SLIM_BPR': 0.01718177806546273, 'P3ALPHA': 0.013003091974868933, 'RP3BETA': 0.02907353591000395, 'IALS': 0.07458521416956278, 'USER_ITEM_ALL': 0.3850569453932251} - Exception: Traceback (most recent call last):
  File "C:\Users\User.LAPTOP-FG37H74P\Documents\GitHub\recsys_2019\src\tuning\SearchFixedObject.py", line 285, in _objective_function
    result_dict, result_string, recommender_instance, train_time, evaluation_time = self._evaluate_on_validation(current_fit_parameters_dict)
  File "C:\Users\User.LAPTOP-FG37H74P\Documents\GitHub\recsys_2019\src\tuning\SearchFixedObject.py", line 196, in _evaluate_on_validation
    result_dict, _ = self.evaluator_validation.evaluateRecommender(recommender_instance)
  File "C:\Users\User.LAPTOP-FG37H74P\Documents\GitHub\recsys_2019\course_lib\Base\Evaluation\Evaluator.py", line 384, in evaluateRecommender
    self.usersToEvaluate)
  File "C:\Users\User.LAPTOP-FG37H74P\Documents\GitHub\recsys_2019\course_lib\Base\Evaluation\Evaluator.py", line 278, in _run_evaluation_on_selected_users
    return_scores=True
  File "C:\Users\User.LAPTOP-FG37H74P\Documents\GitHub\recsys_2019\src\model\HybridRecommender\HybridRankBasedRecommender.py", line 164, in recommend
    rankings, scores = recommender_model.recommend(user_id_array, cutoff=cutoff_model,
AttributeError: 'dict' object has no attribute 'recommend'

SearchBayesianSkoptObject: Config 19 Exception. Config: {'strategy': 'weighted_count', 'multiplier_cutoff': 8, 'MIXED': 0.007845050752884733, 'SLIM_BPR': 0.9996511531891362, 'P3ALPHA': 0.9857292956876542, 'RP3BETA': 0.892510020378706, 'IALS': 0.07190564400371001, 'USER_ITEM_ALL': 0.884607970387065} - Exception: Traceback (most recent call last):
  File "C:\Users\User.LAPTOP-FG37H74P\Documents\GitHub\recsys_2019\src\tuning\SearchFixedObject.py", line 285, in _objective_function
    result_dict, result_string, recommender_instance, train_time, evaluation_time = self._evaluate_on_validation(current_fit_parameters_dict)
  File "C:\Users\User.LAPTOP-FG37H74P\Documents\GitHub\recsys_2019\src\tuning\SearchFixedObject.py", line 196, in _evaluate_on_validation
    result_dict, _ = self.evaluator_validation.evaluateRecommender(recommender_instance)
  File "C:\Users\User.LAPTOP-FG37H74P\Documents\GitHub\recsys_2019\course_lib\Base\Evaluation\Evaluator.py", line 384, in evaluateRecommender
    self.usersToEvaluate)
  File "C:\Users\User.LAPTOP-FG37H74P\Documents\GitHub\recsys_2019\course_lib\Base\Evaluation\Evaluator.py", line 278, in _run_evaluation_on_selected_users
    return_scores=True
  File "C:\Users\User.LAPTOP-FG37H74P\Documents\GitHub\recsys_2019\src\model\HybridRecommender\HybridRankBasedRecommender.py", line 164, in recommend
    rankings, scores = recommender_model.recommend(user_id_array, cutoff=cutoff_model,
AttributeError: 'dict' object has no attribute 'recommend'

SearchBayesianSkoptObject: Config 20 Exception. Config: {'strategy': 'weighted_count', 'multiplier_cutoff': 2, 'MIXED': 0.9856760970867879, 'SLIM_BPR': 0.9848554972181913, 'P3ALPHA': 0.958434893912248, 'RP3BETA': 0.9821836534611483, 'IALS': 0.07123200123676489, 'USER_ITEM_ALL': 0.8952925945460862} - Exception: Traceback (most recent call last):
  File "C:\Users\User.LAPTOP-FG37H74P\Documents\GitHub\recsys_2019\src\tuning\SearchFixedObject.py", line 285, in _objective_function
    result_dict, result_string, recommender_instance, train_time, evaluation_time = self._evaluate_on_validation(current_fit_parameters_dict)
  File "C:\Users\User.LAPTOP-FG37H74P\Documents\GitHub\recsys_2019\src\tuning\SearchFixedObject.py", line 196, in _evaluate_on_validation
    result_dict, _ = self.evaluator_validation.evaluateRecommender(recommender_instance)
  File "C:\Users\User.LAPTOP-FG37H74P\Documents\GitHub\recsys_2019\course_lib\Base\Evaluation\Evaluator.py", line 384, in evaluateRecommender
    self.usersToEvaluate)
  File "C:\Users\User.LAPTOP-FG37H74P\Documents\GitHub\recsys_2019\course_lib\Base\Evaluation\Evaluator.py", line 278, in _run_evaluation_on_selected_users
    return_scores=True
  File "C:\Users\User.LAPTOP-FG37H74P\Documents\GitHub\recsys_2019\src\model\HybridRecommender\HybridRankBasedRecommender.py", line 164, in recommend
    rankings, scores = recommender_model.recommend(user_id_array, cutoff=cutoff_model,
AttributeError: 'dict' object has no attribute 'recommend'

SearchBayesianSkoptObject: Config 21 Exception. Config: {'strategy': 'weighted_count', 'multiplier_cutoff': 1, 'MIXED': 0.9275214789644667, 'SLIM_BPR': 0.0015194624082397472, 'P3ALPHA': 0.9707714195184117, 'RP3BETA': 0.8416013973426034, 'IALS': 0.9419319260441024, 'USER_ITEM_ALL': 0.9627851360285552} - Exception: Traceback (most recent call last):
  File "C:\Users\User.LAPTOP-FG37H74P\Documents\GitHub\recsys_2019\src\tuning\SearchFixedObject.py", line 285, in _objective_function
    result_dict, result_string, recommender_instance, train_time, evaluation_time = self._evaluate_on_validation(current_fit_parameters_dict)
  File "C:\Users\User.LAPTOP-FG37H74P\Documents\GitHub\recsys_2019\src\tuning\SearchFixedObject.py", line 196, in _evaluate_on_validation
    result_dict, _ = self.evaluator_validation.evaluateRecommender(recommender_instance)
  File "C:\Users\User.LAPTOP-FG37H74P\Documents\GitHub\recsys_2019\course_lib\Base\Evaluation\Evaluator.py", line 384, in evaluateRecommender
    self.usersToEvaluate)
  File "C:\Users\User.LAPTOP-FG37H74P\Documents\GitHub\recsys_2019\course_lib\Base\Evaluation\Evaluator.py", line 278, in _run_evaluation_on_selected_users
    return_scores=True
  File "C:\Users\User.LAPTOP-FG37H74P\Documents\GitHub\recsys_2019\src\model\HybridRecommender\HybridRankBasedRecommender.py", line 164, in recommend
    rankings, scores = recommender_model.recommend(user_id_array, cutoff=cutoff_model,
AttributeError: 'dict' object has no attribute 'recommend'

SearchBayesianSkoptObject: Config 22 Exception. Config: {'strategy': 'weighted_count', 'multiplier_cutoff': 2, 'MIXED': 0.9713389293273261, 'SLIM_BPR': 0.9593767040751204, 'P3ALPHA': 0.1572447132065833, 'RP3BETA': 0.008451776773165153, 'IALS': 0.14645059777726008, 'USER_ITEM_ALL': 0.9306967662538197} - Exception: Traceback (most recent call last):
  File "C:\Users\User.LAPTOP-FG37H74P\Documents\GitHub\recsys_2019\src\tuning\SearchFixedObject.py", line 285, in _objective_function
    result_dict, result_string, recommender_instance, train_time, evaluation_time = self._evaluate_on_validation(current_fit_parameters_dict)
  File "C:\Users\User.LAPTOP-FG37H74P\Documents\GitHub\recsys_2019\src\tuning\SearchFixedObject.py", line 196, in _evaluate_on_validation
    result_dict, _ = self.evaluator_validation.evaluateRecommender(recommender_instance)
  File "C:\Users\User.LAPTOP-FG37H74P\Documents\GitHub\recsys_2019\course_lib\Base\Evaluation\Evaluator.py", line 384, in evaluateRecommender
    self.usersToEvaluate)
  File "C:\Users\User.LAPTOP-FG37H74P\Documents\GitHub\recsys_2019\course_lib\Base\Evaluation\Evaluator.py", line 278, in _run_evaluation_on_selected_users
    return_scores=True
  File "C:\Users\User.LAPTOP-FG37H74P\Documents\GitHub\recsys_2019\src\model\HybridRecommender\HybridRankBasedRecommender.py", line 164, in recommend
    rankings, scores = recommender_model.recommend(user_id_array, cutoff=cutoff_model,
AttributeError: 'dict' object has no attribute 'recommend'

SearchBayesianSkoptObject: Config 23 Exception. Config: {'strategy': 'weighted_count', 'multiplier_cutoff': 10, 'MIXED': 0.026700152856865007, 'SLIM_BPR': 0.8223957812986538, 'P3ALPHA': 0.9722389666065557, 'RP3BETA': 0.9385302963930455, 'IALS': 0.872630604540184, 'USER_ITEM_ALL': 0.007072744136897182} - Exception: Traceback (most recent call last):
  File "C:\Users\User.LAPTOP-FG37H74P\Documents\GitHub\recsys_2019\src\tuning\SearchFixedObject.py", line 285, in _objective_function
    result_dict, result_string, recommender_instance, train_time, evaluation_time = self._evaluate_on_validation(current_fit_parameters_dict)
  File "C:\Users\User.LAPTOP-FG37H74P\Documents\GitHub\recsys_2019\src\tuning\SearchFixedObject.py", line 196, in _evaluate_on_validation
    result_dict, _ = self.evaluator_validation.evaluateRecommender(recommender_instance)
  File "C:\Users\User.LAPTOP-FG37H74P\Documents\GitHub\recsys_2019\course_lib\Base\Evaluation\Evaluator.py", line 384, in evaluateRecommender
    self.usersToEvaluate)
  File "C:\Users\User.LAPTOP-FG37H74P\Documents\GitHub\recsys_2019\course_lib\Base\Evaluation\Evaluator.py", line 278, in _run_evaluation_on_selected_users
    return_scores=True
  File "C:\Users\User.LAPTOP-FG37H74P\Documents\GitHub\recsys_2019\src\model\HybridRecommender\HybridRankBasedRecommender.py", line 164, in recommend
    rankings, scores = recommender_model.recommend(user_id_array, cutoff=cutoff_model,
AttributeError: 'dict' object has no attribute 'recommend'

SearchBayesianSkoptObject: Config 24 Exception. Config: {'strategy': 'weighted_count', 'multiplier_cutoff': 10, 'MIXED': 0.07384075078942855, 'SLIM_BPR': 0.2845192943144265, 'P3ALPHA': 0.9716439975603435, 'RP3BETA': 0.009762216046915519, 'IALS': 0.0752723628881471, 'USER_ITEM_ALL': 0.9996728326224328} - Exception: Traceback (most recent call last):
  File "C:\Users\User.LAPTOP-FG37H74P\Documents\GitHub\recsys_2019\src\tuning\SearchFixedObject.py", line 285, in _objective_function
    result_dict, result_string, recommender_instance, train_time, evaluation_time = self._evaluate_on_validation(current_fit_parameters_dict)
  File "C:\Users\User.LAPTOP-FG37H74P\Documents\GitHub\recsys_2019\src\tuning\SearchFixedObject.py", line 196, in _evaluate_on_validation
    result_dict, _ = self.evaluator_validation.evaluateRecommender(recommender_instance)
  File "C:\Users\User.LAPTOP-FG37H74P\Documents\GitHub\recsys_2019\course_lib\Base\Evaluation\Evaluator.py", line 384, in evaluateRecommender
    self.usersToEvaluate)
  File "C:\Users\User.LAPTOP-FG37H74P\Documents\GitHub\recsys_2019\course_lib\Base\Evaluation\Evaluator.py", line 278, in _run_evaluation_on_selected_users
    return_scores=True
  File "C:\Users\User.LAPTOP-FG37H74P\Documents\GitHub\recsys_2019\src\model\HybridRecommender\HybridRankBasedRecommender.py", line 164, in recommend
    rankings, scores = recommender_model.recommend(user_id_array, cutoff=cutoff_model,
AttributeError: 'dict' object has no attribute 'recommend'

SearchBayesianSkoptObject: Config 25 Exception. Config: {'strategy': 'weighted_count', 'multiplier_cutoff': 1, 'MIXED': 0.12580147076382955, 'SLIM_BPR': 0.9567064980227554, 'P3ALPHA': 0.9730541326713684, 'RP3BETA': 0.036064838508741766, 'IALS': 0.8638708403391203, 'USER_ITEM_ALL': 0.02093442390361633} - Exception: Traceback (most recent call last):
  File "C:\Users\User.LAPTOP-FG37H74P\Documents\GitHub\recsys_2019\src\tuning\SearchFixedObject.py", line 285, in _objective_function
    result_dict, result_string, recommender_instance, train_time, evaluation_time = self._evaluate_on_validation(current_fit_parameters_dict)
  File "C:\Users\User.LAPTOP-FG37H74P\Documents\GitHub\recsys_2019\src\tuning\SearchFixedObject.py", line 196, in _evaluate_on_validation
    result_dict, _ = self.evaluator_validation.evaluateRecommender(recommender_instance)
  File "C:\Users\User.LAPTOP-FG37H74P\Documents\GitHub\recsys_2019\course_lib\Base\Evaluation\Evaluator.py", line 384, in evaluateRecommender
    self.usersToEvaluate)
  File "C:\Users\User.LAPTOP-FG37H74P\Documents\GitHub\recsys_2019\course_lib\Base\Evaluation\Evaluator.py", line 278, in _run_evaluation_on_selected_users
    return_scores=True
  File "C:\Users\User.LAPTOP-FG37H74P\Documents\GitHub\recsys_2019\src\model\HybridRecommender\HybridRankBasedRecommender.py", line 164, in recommend
    rankings, scores = recommender_model.recommend(user_id_array, cutoff=cutoff_model,
AttributeError: 'dict' object has no attribute 'recommend'

SearchBayesianSkoptObject: Config 26 Exception. Config: {'strategy': 'weighted_count', 'multiplier_cutoff': 10, 'MIXED': 0.9748960890885523, 'SLIM_BPR': 0.9998060192549288, 'P3ALPHA': 0.7811816386278772, 'RP3BETA': 0.012788154849413761, 'IALS': 0.06276305726972976, 'USER_ITEM_ALL': 0.9740835794203361} - Exception: Traceback (most recent call last):
  File "C:\Users\User.LAPTOP-FG37H74P\Documents\GitHub\recsys_2019\src\tuning\SearchFixedObject.py", line 285, in _objective_function
    result_dict, result_string, recommender_instance, train_time, evaluation_time = self._evaluate_on_validation(current_fit_parameters_dict)
  File "C:\Users\User.LAPTOP-FG37H74P\Documents\GitHub\recsys_2019\src\tuning\SearchFixedObject.py", line 196, in _evaluate_on_validation
    result_dict, _ = self.evaluator_validation.evaluateRecommender(recommender_instance)
  File "C:\Users\User.LAPTOP-FG37H74P\Documents\GitHub\recsys_2019\course_lib\Base\Evaluation\Evaluator.py", line 384, in evaluateRecommender
    self.usersToEvaluate)
  File "C:\Users\User.LAPTOP-FG37H74P\Documents\GitHub\recsys_2019\course_lib\Base\Evaluation\Evaluator.py", line 278, in _run_evaluation_on_selected_users
    return_scores=True
  File "C:\Users\User.LAPTOP-FG37H74P\Documents\GitHub\recsys_2019\src\model\HybridRecommender\HybridRankBasedRecommender.py", line 164, in recommend
    rankings, scores = recommender_model.recommend(user_id_array, cutoff=cutoff_model,
AttributeError: 'dict' object has no attribute 'recommend'

SearchBayesianSkoptObject: Config 27 Exception. Config: {'strategy': 'weighted_count', 'multiplier_cutoff': 9, 'MIXED': 0.9604928402322924, 'SLIM_BPR': 0.948423867206244, 'P3ALPHA': 0.09255142014937569, 'RP3BETA': 0.060696058782965814, 'IALS': 0.9656242537071521, 'USER_ITEM_ALL': 0.029807744181011737} - Exception: Traceback (most recent call last):
  File "C:\Users\User.LAPTOP-FG37H74P\Documents\GitHub\recsys_2019\src\tuning\SearchFixedObject.py", line 285, in _objective_function
    result_dict, result_string, recommender_instance, train_time, evaluation_time = self._evaluate_on_validation(current_fit_parameters_dict)
  File "C:\Users\User.LAPTOP-FG37H74P\Documents\GitHub\recsys_2019\src\tuning\SearchFixedObject.py", line 196, in _evaluate_on_validation
    result_dict, _ = self.evaluator_validation.evaluateRecommender(recommender_instance)
  File "C:\Users\User.LAPTOP-FG37H74P\Documents\GitHub\recsys_2019\course_lib\Base\Evaluation\Evaluator.py", line 384, in evaluateRecommender
    self.usersToEvaluate)
  File "C:\Users\User.LAPTOP-FG37H74P\Documents\GitHub\recsys_2019\course_lib\Base\Evaluation\Evaluator.py", line 278, in _run_evaluation_on_selected_users
    return_scores=True
  File "C:\Users\User.LAPTOP-FG37H74P\Documents\GitHub\recsys_2019\src\model\HybridRecommender\HybridRankBasedRecommender.py", line 164, in recommend
    rankings, scores = recommender_model.recommend(user_id_array, cutoff=cutoff_model,
AttributeError: 'dict' object has no attribute 'recommend'

SearchBayesianSkoptObject: Config 28 Exception. Config: {'strategy': 'weighted_count', 'multiplier_cutoff': 1, 'MIXED': 0.04902457230805225, 'SLIM_BPR': 0.011923995613498887, 'P3ALPHA': 0.8695343840770021, 'RP3BETA': 0.9573373583775884, 'IALS': 0.9369444039686166, 'USER_ITEM_ALL': 0.9778851560447603} - Exception: Traceback (most recent call last):
  File "C:\Users\User.LAPTOP-FG37H74P\Documents\GitHub\recsys_2019\src\tuning\SearchFixedObject.py", line 285, in _objective_function
    result_dict, result_string, recommender_instance, train_time, evaluation_time = self._evaluate_on_validation(current_fit_parameters_dict)
  File "C:\Users\User.LAPTOP-FG37H74P\Documents\GitHub\recsys_2019\src\tuning\SearchFixedObject.py", line 196, in _evaluate_on_validation
    result_dict, _ = self.evaluator_validation.evaluateRecommender(recommender_instance)
  File "C:\Users\User.LAPTOP-FG37H74P\Documents\GitHub\recsys_2019\course_lib\Base\Evaluation\Evaluator.py", line 384, in evaluateRecommender
    self.usersToEvaluate)
  File "C:\Users\User.LAPTOP-FG37H74P\Documents\GitHub\recsys_2019\course_lib\Base\Evaluation\Evaluator.py", line 278, in _run_evaluation_on_selected_users
    return_scores=True
  File "C:\Users\User.LAPTOP-FG37H74P\Documents\GitHub\recsys_2019\src\model\HybridRecommender\HybridRankBasedRecommender.py", line 164, in recommend
    rankings, scores = recommender_model.recommend(user_id_array, cutoff=cutoff_model,
AttributeError: 'dict' object has no attribute 'recommend'

SearchBayesianSkoptObject: Config 29 Exception. Config: {'strategy': 'weighted_count', 'multiplier_cutoff': 10, 'MIXED': 0.9614112137068893, 'SLIM_BPR': 0.858679672983428, 'P3ALPHA': 0.9861599984541335, 'RP3BETA': 0.9962110842291647, 'IALS': 0.9073857513866721, 'USER_ITEM_ALL': 0.0472879919454199} - Exception: Traceback (most recent call last):
  File "C:\Users\User.LAPTOP-FG37H74P\Documents\GitHub\recsys_2019\src\tuning\SearchFixedObject.py", line 285, in _objective_function
    result_dict, result_string, recommender_instance, train_time, evaluation_time = self._evaluate_on_validation(current_fit_parameters_dict)
  File "C:\Users\User.LAPTOP-FG37H74P\Documents\GitHub\recsys_2019\src\tuning\SearchFixedObject.py", line 196, in _evaluate_on_validation
    result_dict, _ = self.evaluator_validation.evaluateRecommender(recommender_instance)
  File "C:\Users\User.LAPTOP-FG37H74P\Documents\GitHub\recsys_2019\course_lib\Base\Evaluation\Evaluator.py", line 384, in evaluateRecommender
    self.usersToEvaluate)
  File "C:\Users\User.LAPTOP-FG37H74P\Documents\GitHub\recsys_2019\course_lib\Base\Evaluation\Evaluator.py", line 278, in _run_evaluation_on_selected_users
    return_scores=True
  File "C:\Users\User.LAPTOP-FG37H74P\Documents\GitHub\recsys_2019\src\model\HybridRecommender\HybridRankBasedRecommender.py", line 164, in recommend
    rankings, scores = recommender_model.recommend(user_id_array, cutoff=cutoff_model,
AttributeError: 'dict' object has no attribute 'recommend'

SearchBayesianSkoptObject: Config 30 Exception. Config: {'strategy': 'weighted_count', 'multiplier_cutoff': 10, 'MIXED': 0.023514424891629037, 'SLIM_BPR': 0.026360739112990896, 'P3ALPHA': 0.0911178931334262, 'RP3BETA': 0.031065213167024992, 'IALS': 0.04552950911156565, 'USER_ITEM_ALL': 0.019291895531981476} - Exception: Traceback (most recent call last):
  File "C:\Users\User.LAPTOP-FG37H74P\Documents\GitHub\recsys_2019\src\tuning\SearchFixedObject.py", line 285, in _objective_function
    result_dict, result_string, recommender_instance, train_time, evaluation_time = self._evaluate_on_validation(current_fit_parameters_dict)
  File "C:\Users\User.LAPTOP-FG37H74P\Documents\GitHub\recsys_2019\src\tuning\SearchFixedObject.py", line 196, in _evaluate_on_validation
    result_dict, _ = self.evaluator_validation.evaluateRecommender(recommender_instance)
  File "C:\Users\User.LAPTOP-FG37H74P\Documents\GitHub\recsys_2019\course_lib\Base\Evaluation\Evaluator.py", line 384, in evaluateRecommender
    self.usersToEvaluate)
  File "C:\Users\User.LAPTOP-FG37H74P\Documents\GitHub\recsys_2019\course_lib\Base\Evaluation\Evaluator.py", line 278, in _run_evaluation_on_selected_users
    return_scores=True
  File "C:\Users\User.LAPTOP-FG37H74P\Documents\GitHub\recsys_2019\src\model\HybridRecommender\HybridRankBasedRecommender.py", line 164, in recommend
    rankings, scores = recommender_model.recommend(user_id_array, cutoff=cutoff_model,
AttributeError: 'dict' object has no attribute 'recommend'

SearchBayesianSkoptObject: Config 31 Exception. Config: {'strategy': 'weighted_count', 'multiplier_cutoff': 9, 'MIXED': 0.004671350478369641, 'SLIM_BPR': 0.8266137042527661, 'P3ALPHA': 0.008579672977865884, 'RP3BETA': 0.9566618820342445, 'IALS': 0.0933262843616335, 'USER_ITEM_ALL': 0.9792546629013983} - Exception: Traceback (most recent call last):
  File "C:\Users\User.LAPTOP-FG37H74P\Documents\GitHub\recsys_2019\src\tuning\SearchFixedObject.py", line 285, in _objective_function
    result_dict, result_string, recommender_instance, train_time, evaluation_time = self._evaluate_on_validation(current_fit_parameters_dict)
  File "C:\Users\User.LAPTOP-FG37H74P\Documents\GitHub\recsys_2019\src\tuning\SearchFixedObject.py", line 196, in _evaluate_on_validation
    result_dict, _ = self.evaluator_validation.evaluateRecommender(recommender_instance)
  File "C:\Users\User.LAPTOP-FG37H74P\Documents\GitHub\recsys_2019\course_lib\Base\Evaluation\Evaluator.py", line 384, in evaluateRecommender
    self.usersToEvaluate)
  File "C:\Users\User.LAPTOP-FG37H74P\Documents\GitHub\recsys_2019\course_lib\Base\Evaluation\Evaluator.py", line 278, in _run_evaluation_on_selected_users
    return_scores=True
  File "C:\Users\User.LAPTOP-FG37H74P\Documents\GitHub\recsys_2019\src\model\HybridRecommender\HybridRankBasedRecommender.py", line 164, in recommend
    rankings, scores = recommender_model.recommend(user_id_array, cutoff=cutoff_model,
AttributeError: 'dict' object has no attribute 'recommend'

SearchBayesianSkoptObject: Config 32 Exception. Config: {'strategy': 'weighted_count', 'multiplier_cutoff': 1, 'MIXED': 0.04372638759241255, 'SLIM_BPR': 0.9709794713149479, 'P3ALPHA': 0.9275857710633028, 'RP3BETA': 0.047573713050244396, 'IALS': 0.027925275478811414, 'USER_ITEM_ALL': 0.2005333230671958} - Exception: Traceback (most recent call last):
  File "C:\Users\User.LAPTOP-FG37H74P\Documents\GitHub\recsys_2019\src\tuning\SearchFixedObject.py", line 285, in _objective_function
    result_dict, result_string, recommender_instance, train_time, evaluation_time = self._evaluate_on_validation(current_fit_parameters_dict)
  File "C:\Users\User.LAPTOP-FG37H74P\Documents\GitHub\recsys_2019\src\tuning\SearchFixedObject.py", line 196, in _evaluate_on_validation
    result_dict, _ = self.evaluator_validation.evaluateRecommender(recommender_instance)
  File "C:\Users\User.LAPTOP-FG37H74P\Documents\GitHub\recsys_2019\course_lib\Base\Evaluation\Evaluator.py", line 384, in evaluateRecommender
    self.usersToEvaluate)
  File "C:\Users\User.LAPTOP-FG37H74P\Documents\GitHub\recsys_2019\course_lib\Base\Evaluation\Evaluator.py", line 278, in _run_evaluation_on_selected_users
    return_scores=True
  File "C:\Users\User.LAPTOP-FG37H74P\Documents\GitHub\recsys_2019\src\model\HybridRecommender\HybridRankBasedRecommender.py", line 164, in recommend
    rankings, scores = recommender_model.recommend(user_id_array, cutoff=cutoff_model,
AttributeError: 'dict' object has no attribute 'recommend'

SearchBayesianSkoptObject: Config 33 Exception. Config: {'strategy': 'weighted_count', 'multiplier_cutoff': 1, 'MIXED': 0.9358900354237417, 'SLIM_BPR': 0.3664974827088158, 'P3ALPHA': 0.010463560823478992, 'RP3BETA': 0.9552063095635501, 'IALS': 0.9625195270028112, 'USER_ITEM_ALL': 0.9892237051312722} - Exception: Traceback (most recent call last):
  File "C:\Users\User.LAPTOP-FG37H74P\Documents\GitHub\recsys_2019\src\tuning\SearchFixedObject.py", line 285, in _objective_function
    result_dict, result_string, recommender_instance, train_time, evaluation_time = self._evaluate_on_validation(current_fit_parameters_dict)
  File "C:\Users\User.LAPTOP-FG37H74P\Documents\GitHub\recsys_2019\src\tuning\SearchFixedObject.py", line 196, in _evaluate_on_validation
    result_dict, _ = self.evaluator_validation.evaluateRecommender(recommender_instance)
  File "C:\Users\User.LAPTOP-FG37H74P\Documents\GitHub\recsys_2019\course_lib\Base\Evaluation\Evaluator.py", line 384, in evaluateRecommender
    self.usersToEvaluate)
  File "C:\Users\User.LAPTOP-FG37H74P\Documents\GitHub\recsys_2019\course_lib\Base\Evaluation\Evaluator.py", line 278, in _run_evaluation_on_selected_users
    return_scores=True
  File "C:\Users\User.LAPTOP-FG37H74P\Documents\GitHub\recsys_2019\src\model\HybridRecommender\HybridRankBasedRecommender.py", line 164, in recommend
    rankings, scores = recommender_model.recommend(user_id_array, cutoff=cutoff_model,
AttributeError: 'dict' object has no attribute 'recommend'

SearchBayesianSkoptObject: Config 34 Exception. Config: {'strategy': 'weighted_count', 'multiplier_cutoff': 9, 'MIXED': 0.8907099290400019, 'SLIM_BPR': 0.12220944891202182, 'P3ALPHA': 0.08163149117615044, 'RP3BETA': 0.054515452391685995, 'IALS': 0.9881816980532382, 'USER_ITEM_ALL': 0.9475437294785755} - Exception: Traceback (most recent call last):
  File "C:\Users\User.LAPTOP-FG37H74P\Documents\GitHub\recsys_2019\src\tuning\SearchFixedObject.py", line 285, in _objective_function
    result_dict, result_string, recommender_instance, train_time, evaluation_time = self._evaluate_on_validation(current_fit_parameters_dict)
  File "C:\Users\User.LAPTOP-FG37H74P\Documents\GitHub\recsys_2019\src\tuning\SearchFixedObject.py", line 196, in _evaluate_on_validation
    result_dict, _ = self.evaluator_validation.evaluateRecommender(recommender_instance)
  File "C:\Users\User.LAPTOP-FG37H74P\Documents\GitHub\recsys_2019\course_lib\Base\Evaluation\Evaluator.py", line 384, in evaluateRecommender
    self.usersToEvaluate)
  File "C:\Users\User.LAPTOP-FG37H74P\Documents\GitHub\recsys_2019\course_lib\Base\Evaluation\Evaluator.py", line 278, in _run_evaluation_on_selected_users
    return_scores=True
  File "C:\Users\User.LAPTOP-FG37H74P\Documents\GitHub\recsys_2019\src\model\HybridRecommender\HybridRankBasedRecommender.py", line 164, in recommend
    rankings, scores = recommender_model.recommend(user_id_array, cutoff=cutoff_model,
AttributeError: 'dict' object has no attribute 'recommend'

SearchBayesianSkoptObject: Search complete. Best config is None: None
